Workbook

Sheet Pivot
A3: Sum of Weighted $ | B3: Column Labels
A4: Row Labels | B4: North Team | C4: South Team | D4: Waterfront Team | E4: Grand Total
A5: Closed Lost | B5: 0 | D5: 0 | E5: 0
A6: Closed Won | B6: 2518000 | C6: 1592000 | D6: 3273000 | E6: 7383000
A7: Lead | B7: 91220 | C7: 23050 | D7: 147660 | E7: 261930
A8: Offer | B8: 947750 | C8: 138650 | D8: 484300 | E8: 1570700
A9: Qualified | B9: 450090 | C9: 178800 | D9: 433900 | E9: 1062790
A10: Showing | C10: 1231590 | D10: 91680 | E10: 1323270
A11: Under Contract | B11: 2134180 | C11: 957480 | D11: 205140 | E11: 3296800
A12: Grand Total | B12: 6141240 | C12: 4121570 | D12: 4635680 | E12: 14898490

Sheet Deals
A1: DealID | B1: Agent | C1: City | D1: Stage | E1: Value | F1: Probability | G1: CreatedDate | H1: CloseDate | I1: LastActivityDate | J1: ActivityCount | K1: Agent (clean) | L1: Weighted $ | M1: Team | N1: Priority
A2: D1001 | B2: sofia rossi | C2: Tampa | D2: Lead | E2: 461000 | F2: 0.05 | G2: 46128 | I2: 46195 | J2: 35 | K2: =TRIM(PROPER(B2)) -> Sofia Rossi | L2: =E2*F2 -> 23050 | M2: =_xlfn.XLOOKUP(K2,Agents!A:A,Agents!B:B,"-") -> South Team | N2: {=_xlfn.IFS(F2>=0.7,"High", F2>=0.4,"Medium", TRUE,"Low")} -> Low
A3: D1002 | B3: maria garcia | C3: Riverview | D3: Under Contract | E3: 210000 | F3: 0.84 | G3: 46167 | I3: 46196 | J3: 2 | K3: =TRIM(PROPER(B3)) -> Maria Garcia | L3: =E3*F3 -> 176400 | M3: =_xlfn.XLOOKUP(K3,Agents!A:A,Agents!B:B,"-") -> North Team | N3: {=_xlfn.IFS(F3>=0.7,"High", F3>=0.4,"Medium", TRUE,"Low")} -> High
A4: D1003 | B4: CHEN WEI | C4: Clearwater | D4: Qualified | E4: 738000 | F4: 0.28 | G4: 46083 | I4: 46195 | J4: 1 | K4: =TRIM(PROPER(B4)) -> Chen Wei | L4: =E4*F4 -> 206640 | M4: =_xlfn.XLOOKUP(K4,Agents!A:A,Agents!B:B,"-") -> Waterfront Team | N4: {=_xlfn.IFS(F4>=0.7,"High", F4>=0.4,"Medium", TRUE,"Low")} -> Low
A5: D1004 | B5: james o'brien | C5: Largo | D5: Closed Won | E5: 612000 | F5: 1 | G5: 46103 | H5: 46150 | I5: 46150 | J5: 22 | K5: =TRIM(PROPER(B5)) -> James O'Brien | L5: =E5*F5 -> 612000 | M5: =_xlfn.XLOOKUP(K5,Agents!A:A,Agents!B:B,"-") -> Waterfront Team | N5: {=_xlfn.IFS(F5>=0.7,"High", F5>=0.4,"Medium", TRUE,"Low")} -> High
A6: D1005 | B6: maria garcia | C6: Tampa | D6: Lead | E6: 547000 | F6: 0.08 | G6: 46102 | I6: 46171 | J6: 30 | K6: =TRIM(PROPER(B6)) -> Maria Garcia | L6: =E6*F6 -> 43760 | M6: =_xlfn.XLOOKUP(K6,Agents!A:A,Agents!B:B,"-") -> North Team | N6: {=_xlfn.IFS(F6>=0.7,"High", F6>=0.4,"Medium", TRUE,"Low")} -> Low
A7: D1006 | B7: chen wei | C7: Wesley Chapel | D7: Lead | E7: 567000 | F7: 0.18 | G7: 46170 | I7: 46174 | J7: 24 | K7: =TRIM(PROPER(B7)) -> Chen Wei | L7: =E7*F7 -> 102060 | M7: =_xlfn.XLOOKUP(K7,Agents!A:A,Agents!B:B,"-") -> Waterfront Team | N7: {=_xlfn.IFS(F7>=0.7,"High", F7>=0.4,"Medium", TRUE,"Low")} -> Low
A8: D1007 | B8: chen wei | C8: Tampa | D8: Qualified | E8: 226000 | F8: 0.28 | G8: 46132 | I8: 46160 | J8: 15 | K8: =TRIM(PROPER(B8)) -> Chen Wei | L8: =E8*F8 -> 63280 | M8: =_xlfn.XLOOKUP(K8,Agents!A:A,Agents!B:B,"-") -> Waterfront Team | N8: {=_xlfn.IFS(F8>=0.7,"High", F8>=0.4,"Medium", TRUE,"Low")} -> Low
A9: D1008 | B9: MARIA GARCIA | C9: St. Petersburg | D9: Offer | E9: 830000 | F9: 0.56 | G9: 46097 | I9: 46199 | J9: 18 | K9: =TRIM(PROPER(B9)) -> Maria Garcia | L9: =E9*F9 -> 464800 | M9: =_xlfn.XLOOKUP(K9,Agents!A:A,Agents!B:B,"-") -> North Team | N9: {=_xlfn.IFS(F9>=0.7,"High", F9>=0.4,"Medium", TRUE,"Low")} -> Medium
A10: D1009 | B10: Sofia Rossi | C10: Riverview | D10: Closed Won | E10: 843000 | F10: 1 | G10: 46172 | H10: 46240 | I10: 46240 | J10: 16 | K10: =TRIM(PROPER(B10)) -> Sofia Rossi | L10: =E10*F10 -> 843000 | M10: =_xlfn.XLOOKUP(K10,Agents!A:A,Agents!B:B,"-") -> South Team | N10: {=_xlfn.IFS(F10>=0.7,"High", F10>=0.4,"Medium", TRUE,"Low")} -> High
A11: D1010 | B11: James O'Brien | C11: Largo | D11: Offer | E11: 835000 | F11: 0.58 | G11: 46048 | I11: 46195 | J11: 4 | K11: =TRIM(PROPER(B11)) -> James O'Brien | L11: =E11*F11 -> 484300 | M11: =_xlfn.XLOOKUP(K11,Agents!A:A,Agents!B:B,"-") -> Waterfront Team | N11: {=_xlfn.IFS(F11>=0.7,"High", F11>=0.4,"Medium", TRUE,"Low")} -> Medium
A12: D1011 | B12: james o'brien | C12: St. Petersburg | D12: Closed Lost | E12: 212000 | F12: 0 | G12: 46110 | H12: 46165 | I12: 46165 | J12: 37 | K12: =TRIM(PROPER(B12)) -> James O'Brien | L12: =E12*F12 -> 0 | M12: =_xlfn.XLOOKUP(K12,Agents!A:A,Agents!B:B,"-") -> Waterfront Team | N12: {=_xlfn.IFS(F12>=0.7,"High", F12>=0.4,"Medium", TRUE,"Low")} -> Low
A13: D1012 | B13: SOFIA ROSSI | C13: Clearwater | D13: Showing | E13: 691000 | F13: 0.35 | G13: 46089 | I13: 46168 | J13: 9 | K13: =TRIM(PROPER(B13)) -> Sofia Rossi | L13: =E13*F13 -> 241850 | M13: =_xlfn.XLOOKUP(K13,Agents!A:A,Agents!B:B,"-") -> South Team | N13: {=_xlfn.IFS(F13>=0.7,"High", F13>=0.4,"Medium", TRUE,"Low")} -> Low
A14: D1013 | B14: james o'brien | C14: Brandon | D14: Closed Won | E14: 754000 | F14: 1 | G14: 46053 | H14: 46099 | I14: 46099 | J14: 38 | K14: =TRIM(PROPER(B14)) -> James O'Brien | L14: =E14*F14 -> 754000 | M14: =_xlfn.XLOOKUP(K14,Agents!A:A,Agents!B:B,"-") -> Waterfront Team | N14: {=_xlfn.IFS(F14>=0.7,"High", F14>=0.4,"Medium", TRUE,"Low")} -> High
A15: D1014 | B15: david washington | C15: Tampa | D15: Showing | E15: 321000 | F15: 0.36 | G15: 46060 | I15: 46178 | J15: 8 | K15: =TRIM(PROPER(B15)) -> David Washington | L15: =E15*F15 -> 115560 | M15: =_xlfn.XLOOKUP(K15,Agents!A:A,Agents!B:B,"-") -> South Team | N15: {=_xlfn.IFS(F15>=0.7,"High", F15>=0.4,"Medium", TRUE,"Low")} -> Low
A16: D1015 | B16: james o'brien | C16: Brandon | D16: Closed Won | E16: 343000 | F16: 1 | G16: 46082 | H16: 46150 | I16: 46150 | J16: 30 | K16: =TRIM(PROPER(B16)) -> James O'Brien | L16: =E16*F16 -> 343000 | M16: =_xlfn.XLOOKUP(K16,Agents!A:A,Agents!B:B,"-") -> Waterfront Team | N16: {=_xlfn.IFS(F16>=0.7,"High", F16>=0.4,"Medium", TRUE,"Low")} -> High
A17: D1016 | B17: Chen Wei | C17: Largo | D17: Showing | E17: 191000 | F17: 0.48 | G17: 46161 | I17: 46166 | J17: 18 | K17: =TRIM(PROPER(B17)) -> Chen Wei | L17: =E17*F17 -> 91680 | M17: =_xlfn.XLOOKUP(K17,Agents!A:A,Agents!B:B,"-") -> Waterfront Team | N17: {=_xlfn.IFS(F17>=0.7,"High", F17>=0.4,"Medium", TRUE,"Low")} -> Medium
A18: D1017 | B18: sofia rossi | C18: Wesley Chapel | D18: Showing | E18: 625000 | F18: 0.34 | G18: 46150 | I18: 46180 | J18: 17 | K18: =TRIM(PROPER(B18)) -> Sofia Rossi | L18: =E18*F18 -> 212500 | M18: =_xlfn.XLOOKUP(K18,Agents!A:A,Agents!B:B,"-") -> South Team | N18: {=_xlfn.IFS(F18>=0.7,"High", F18>=0.4,"Medium", TRUE,"Low")} -> Low
A19: D1018 | B19: chen wei | C19: Wesley Chapel | D19: Closed Lost | E19: 362000 | F19: 0 | G19: 46061 | H19: 46149 | I19: 46149 | J19: 20 | K19: =TRIM(PROPER(B19)) -> Chen Wei | L19: =E19*F19 -> 0 | M19: =_xlfn.XLOOKUP(K19,Agents!A:A,Agents!B:B,"-") -> Waterfront Team | N19: {=_xlfn.IFS(F19>=0.7,"High", F19>=0.4,"Medium", TRUE,"Low")} -> Low
A20: D1019 | B20: sofia rossi | C20: Largo | D20: Under Contract | E20: 336000 | F20: 0.87 | G20: 46095 | I20: 46161 | J20: 34 | K20: =TRIM(PROPER(B20)) -> Sofia Rossi | L20: =E20*F20 -> 292320 | M20: =_xlfn.XLOOKUP(K20,Agents!A:A,Agents!B:B,"-") -> South Team | N20: {=_xlfn.IFS(F20>=0.7,"High", F20>=0.4,"Medium", TRUE,"Low")} -> High
A21: D1020 | B21: Maria Garcia | C21: Largo | D21: Under Contract | E21: 199000 | F21: 0.82 | G21: 46162 | I21: 46186 | J21: 20 | K21: =TRIM(PROPER(B21)) -> Maria Garcia | L21: =E21*F21 -> 163180 | M21: =_xlfn.XLOOKUP(K21,Agents!A:A,Agents!B:B,"-") -> North Team | N21: {=_xlfn.IFS(F21>=0.7,"High", F21>=0.4,"Medium", TRUE,"Low")} -> High
A22: D1021 | B22: james o'brien | C22: Largo | D22: Lead | E22: 760000 | F22: 0.06 | G22: 46170 | I22: 46204 | J22: 5 | K22: =TRIM(PROPER(B22)) -> James O'Brien | L22: =E22*F22 -> 45600 | M22: =_xlfn.XLOOKUP(K22,Agents!A:A,Agents!B:B,"-") -> Waterfront Team | N22: {=_xlfn.IFS(F22>=0.7,"High", F22>=0.4,"Medium", TRUE,"Low")} -> Low
A23: D1022 | B23: CHEN WEI | C23: Riverview | D23: Closed Lost | E23: 308000 | F23: 0 | G23: 46158 | H23: 46230 | I23: 46230 | J23: 11 | K23: =TRIM(PROPER(B23)) -> Chen Wei | L23: =E23*F23 -> 0 | M23: =_xlfn.XLOOKUP(K23,Agents!A:A,Agents!B:B,"-") -> Waterfront Team | N23: {=_xlfn.IFS(F23>=0.7,"High", F23>=0.4,"Medium", TRUE,"Low")} -> Low
A24: D1023 | B24: priya patel | C24: Wesley Chapel | D24: Under Contract | E24: 613000 | F24: 0.91 | G24: 46136 | I24: 46175 | J24: 13 | K24: =TRIM(PROPER(B24)) -> Priya Patel | L24: =E24*F24 -> 557830 | M24: =_xlfn.XLOOKUP(K24,Agents!A:A,Agents!B:B,"-") -> North Team | N24: {=_xlfn.IFS(F24>=0.7,"High", F24>=0.4,"Medium", TRUE,"Low")} -> High
A25: D1024 | B25: Sofia Rossi | C25: Brandon | D25: Showing | E25: 845000 | F25: 0.38 | G25: 46095 | I25: 46181 | J25: 8 | K25: =TRIM(PROPER(B25)) -> Sofia Rossi | L25: =E25*F25 -> 321100 | M25: =_xlfn.XLOOKUP(K25,Agents!A:A,Agents!B:B,"-") -> South Team | N25: {=_xlfn.IFS(F25>=0.7,"High", F25>=0.4,"Medium", TRUE,"Low")} -> Low
A26: D1025 | B26: james o'brien | C26: St. Petersburg | D26: Qualified | E26: 201000 | F26: 0.18 | G26: 46040 | I26: 46174 | J26: 1 | K26: =TRIM(PROPER(B26)) -> James O'Brien | L26: =E26*F26 -> 36180 | M26: =_xlfn.XLOOKUP(K26,Agents!A:A,Agents!B:B,"-") -> Waterfront Team | N26: {=_xlfn.IFS(F26>=0.7,"High", F26>=0.4,"Medium", TRUE,"Low")} -> Low
A27: D1026 | B27: maria garcia | C27: Tampa | D27: Closed Won | E27: 826000 | F27: 1 | G27: 46175 | H27: 46219 | I27: 46219 | J27: 22 | K27: =TRIM(PROPER(B27)) -> Maria Garcia | L27: =E27*F27 -> 826000 | M27: =_xlfn.XLOOKUP(K27,Agents!A:A,Agents!B:B,"-") -> North Team | N27: {=_xlfn.IFS(F27>=0.7,"High", F27>=0.4,"Medium", TRUE,"Low")} -> High
A28: D1027 | B28: maria garcia | C28: Riverview | D28: Under Contract | E28: 677000 | F28: 0.81 | G28: 46136 | I28: 46175 | J28: 37 | K28: =TRIM(PROPER(B28)) -> Maria Garcia | L28: =E28*F28 -> 548370 | M28: =_xlfn.XLOOKUP(K28,Agents!A:A,Agents!B:B,"-") -> North Team | N28: {=_xlfn.IFS(F28>=0.7,"High", F28>=0.4,"Medium", TRUE,"Low")} -> High
A29: D1028 | B29: david washington | C29: Brandon | D29: Qualified | E29: 596000 | F29: 0.3 | G29: 46142 | I29: 46203 | J29: 23 | K29: =TRIM(PROPER(B29)) -> David Washington | L29: =E29*F29 -> 178800 | M29: =_xlfn.XLOOKUP(K29,Agents!A:A,Agents!B:B,"-") -> South Team | N29: {=_xlfn.IFS(F29>=0.7,"High", F29>=0.4,"Medium", TRUE,"Low")} -> Low
A30: D1029 | B30: DAVID WASHINGTON | C30: Clearwater | D30: Offer | E30: 235000 | F30: 0.59 | G30: 46165 | I30: 46206 | J30: 7 | K30: =TRIM(PROPER(B30)) -> David Washington | L30: =E30*F30 -> 138650 | M30: =_xlfn.XLOOKUP(K30,Agents!A:A,Agents!B:B,"-") -> South Team | N30: {=_xlfn.IFS(F30>=0.7,"High", F30>=0.4,"Medium", TRUE,"Low")} -> Medium
A31: D1030 | B31: james o'brien | C31: Brandon | D31: Qualified | E31: 639000 | F31: 0.2 | G31: 46155 | I31: 46182 | J31: 16 | K31: =TRIM(PROPER(B31)) -> James O'Brien | L31: =E31*F31 -> 127800 | M31: =_xlfn.XLOOKUP(K31,Agents!A:A,Agents!B:B,"-") -> Waterfront Team | N31: {=_xlfn.IFS(F31>=0.7,"High", F31>=0.4,"Medium", TRUE,"Low")} -> Low
A32: D1031 | B32: Maria Garcia | C32: Riverview | D32: Offer | E32: 743000 | F32: 0.65 | G32: 46165 | I32: 46206 | J32: 1 | K32: =TRIM(PROPER(B32)) -> Maria Garcia | L32: =E32*F32 -> 482950 | M32: =_xlfn.XLOOKUP(K32,Agents!A:A,Agents!B:B,"-") -> North Team | N32: {=_xlfn.IFS(F32>=0.7,"High", F32>=0.4,"Medium", TRUE,"Low")} -> Medium
A33: D1032 | B33: MARIA GARCIA | C33: St. Petersburg | D33: Closed Lost | E33: 422000 | F33: 0 | G33: 46148 | H33: 46204 | I33: 46204 | J33: 26 | K33: =TRIM(PROPER(B33)) -> Maria Garcia | L33: =E33*F33 -> 0 | M33: =_xlfn.XLOOKUP(K33,Agents!A:A,Agents!B:B,"-") -> North Team | N33: {=_xlfn.IFS(F33>=0.7,"High", F33>=0.4,"Medium", TRUE,"Low")} -> Low
A34: D1033 | B34: maria garcia | C34: Clearwater | D34: Qualified | E34: 579000 | F34: 0.23 | G34: 46123 | I34: 46159 | J34: 28 | K34: =TRIM(PROPER(B34)) -> Maria Garcia | L34: =E34*F34 -> 133170 | M34: =_xlfn.XLOOKUP(K34,Agents!A:A,Agents!B:B,"-") -> North Team | N34: {=_xlfn.IFS(F34>=0.7,"High", F34>=0.4,"Medium", TRUE,"Low")} -> Low
A35: D1034 | B35: sofia rossi | C35: St. Petersburg | D35: Closed Won | E35: 749000 | F35: 1 | G35: 46066 | H35: 46105 | I35: 46105 | J35: 4 | K35: =TRIM(PROPER(B35)) -> Sofia Rossi | L35: =E35*F35 -> 749000 | M35: =_xlfn.XLOOKUP(K35,Agents!A:A,Agents!B:B,"-") -> South Team | N35: {=_xlfn.IFS(F35>=0.7,"High", F35>=0.4,"Medium", TRUE,"Low")} -> High
A36: D1035 | B36: CHEN WEI | C36: Tampa | D36: Closed Won | E36: 735000 | F36: 1 | G36: 46175 | H36: 46252 | I36: 46252 | J36: 38 | K36: =TRIM(PROPER(B36)) -> Chen Wei | L36: =E36*F36 -> 735000 | M36: =_xlfn.XLOOKUP(K36,Agents!A:A,Agents!B:B,"-") -> Waterfront Team | N36: {=_xlfn.IFS(F36>=0.7,"High", F36>=0.4,"Medium", TRUE,"Low")} -> High
A37: D1036 | B37: David Washington | C37: Tampa | D37: Under Contract | E37: 723000 | F37: 0.92 | G37: 46150 | I37: 46206 | J37: 12 | K37: =TRIM(PROPER(B37)) -> David Washington | L37: =E37*F37 -> 665160 | M37: =_xlfn.XLOOKUP(K37,Agents!A:A,Agents!B:B,"-") -> South Team | N37: {=_xlfn.IFS(F37>=0.7,"High", F37>=0.4,"Medium", TRUE,"Low")} -> High
A38: D1037 | B38: Maria Garcia | C38: Riverview | D38: Under Contract | E38: 420000 | F38: 0.78 | G38: 46087 | I38: 46202 | J38: 16 | K38: =TRIM(PROPER(B38)) -> Maria Garcia | L38: =E38*F38 -> 327600 | M38: =_xlfn.XLOOKUP(K38,Agents!A:A,Agents!B:B,"-") -> North Team | N38: {=_xlfn.IFS(F38>=0.7,"High", F38>=0.4,"Medium", TRUE,"Low")} -> High
A39: D1038 | B39: Chen Wei | C39: Riverview | D39: Under Contract | E39: 263000 | F39: 0.78 | G39: 46083 | I39: 46167 | J39: 21 | K39: =TRIM(PROPER(B39)) -> Chen Wei | L39: =E39*F39 -> 205140 | M39: =_xlfn.XLOOKUP(K39,Agents!A:A,Agents!B:B,"-") -> Waterfront Team | N39: {=_xlfn.IFS(F39>=0.7,"High", F39>=0.4,"Medium", TRUE,"Low")} -> High
A40: D1039 | B40: PRIYA PATEL | C40: Wesley Chapel | D40: Qualified | E40: 501000 | F40: 0.28 | G40: 46129 | I40: 46193 | J40: 20 | K40: =TRIM(PROPER(B40)) -> Priya Patel | L40: =E40*F40 -> 140280 | M40: =_xlfn.XLOOKUP(K40,Agents!A:A,Agents!B:B,"-") -> North Team | N40: {=_xlfn.IFS(F40>=0.7,"High", F40>=0.4,"Medium", TRUE,"Low")} -> Low
...

Sheet Agents
A1: Agent | B1: Team | C1: Region
A2: Maria Garcia | B2: North Team | C2: Hillsborough
A3: James O'Brien | B3: Waterfront Team | C3: Pinellas
A4: Priya Patel | B4: North Team | C4: Pasco
A5: David Washington | B5: South Team | C5: Hillsborough
A6: Chen Wei | B6: Waterfront Team | C6: Pinellas
A7: Sofia Rossi | B7: South Team | C7: Hillsborough

Sheet Summary
A1: Stage | B1: Weighted Pipeline | D1: Agent | E1: Deals | F1: Avg Value
A2: Lead | B2: =SUMIFS(Deals!L:L, Deals!D:D, A2) -> 261930 | D2: Maria Garcia | E2: =COUNTIFS(Deals!K:K, D2) -> 15 | F2: =AVERAGEIFS(Deals!E:E, Deals!K:K, D2) -> 529000
A3: Qualified | B3: =SUMIFS(Deals!L:L, Deals!D:D, A3) -> 1062790 | D3: James O'Brien | E3: =COUNTIFS(Deals!K:K, D3) -> 9 | F3: =AVERAGEIFS(Deals!E:E, Deals!K:K, D3) -> 576111.11
A4: Showing | B4: =SUMIFS(Deals!L:L, Deals!D:D, A4) -> 1323270 | D4: Priya Patel | E4: =COUNTIFS(Deals!K:K, D4) -> 3 | F4: =AVERAGEIFS(Deals!E:E, Deals!K:K, D4) -> 616666.67
A5: Offer | B5: =SUMIFS(Deals!L:L, Deals!D:D, A5) -> 1570700 | D5: David Washington | E5: =COUNTIFS(Deals!K:K, D5) -> 5 | F5: =AVERAGEIFS(Deals!E:E, Deals!K:K, D5) -> 425800
A6: Under Contract | B6: =SUMIFS(Deals!L:L, Deals!D:D, A6) -> 3296800 | D6: Chen Wei | E6: =COUNTIFS(Deals!K:K, D6) -> 8 | F6: =AVERAGEIFS(Deals!E:E, Deals!K:K, D6) -> 423750
A7: Closed Won | B7: =SUMIFS(Deals!L:L, Deals!D:D, A7) -> 7383000 | D7: Sofia Rossi | E7: =COUNTIFS(Deals!K:K, D7) -> 8 | F7: =AVERAGEIFS(Deals!E:E, Deals!K:K, D7) -> 647750
A8: Closed Lost | B8: =SUMIFS(Deals!L:L, Deals!D:D, A8) -> 0
